2022-02-08 09:58:55,697 ERROR: Exception on /edit_profile [POST] [in C:\Users\Acer\PycharmProjects\pythonProject\pythonProject\MicroBlog-Mega-Toturial\NATO-alphabet-start\lib\site-packages\flask\app.py:1457]
Traceback (most recent call last):
  File "C:\Users\Acer\PycharmProjects\pythonProject\pythonProject\MicroBlog-Mega-Toturial\NATO-alphabet-start\lib\site-packages\flask\app.py", line 2073, in wsgi_app
    response = self.full_dispatch_request()
  File "C:\Users\Acer\PycharmProjects\pythonProject\pythonProject\MicroBlog-Mega-Toturial\NATO-alphabet-start\lib\site-packages\flask\app.py", line 1518, in full_dispatch_request
    rv = self.handle_user_exception(e)
  File "C:\Users\Acer\PycharmProjects\pythonProject\pythonProject\MicroBlog-Mega-Toturial\NATO-alphabet-start\lib\site-packages\flask\app.py", line 1516, in full_dispatch_request
    rv = self.dispatch_request()
  File "C:\Users\Acer\PycharmProjects\pythonProject\pythonProject\MicroBlog-Mega-Toturial\NATO-alphabet-start\lib\site-packages\flask\app.py", line 1502, in dispatch_request
    return self.ensure_sync(self.view_functions[rule.endpoint])(**req.view_args)
  File "C:\Users\Acer\PycharmProjects\pythonProject\pythonProject\MicroBlog-Mega-Toturial\NATO-alphabet-start\lib\site-packages\flask_login\utils.py", line 272, in decorated_view
    return func(*args, **kwargs)
  File "C:\Users\Acer\PycharmProjects\pythonProject\pythonProject\MicroBlog-Mega-Toturial\app\routes.py", line 96, in edit_profile
    if form.validate_on_submit():
  File "C:\Users\Acer\PycharmProjects\pythonProject\pythonProject\MicroBlog-Mega-Toturial\NATO-alphabet-start\lib\site-packages\flask_wtf\form.py", line 86, in validate_on_submit
    return self.is_submitted() and self.validate()
  File "C:\Users\Acer\PycharmProjects\pythonProject\pythonProject\MicroBlog-Mega-Toturial\NATO-alphabet-start\lib\site-packages\wtforms\form.py", line 329, in validate
    return super().validate(extra)
  File "C:\Users\Acer\PycharmProjects\pythonProject\pythonProject\MicroBlog-Mega-Toturial\NATO-alphabet-start\lib\site-packages\wtforms\form.py", line 146, in validate
    if not field.validate(self, extra):
  File "C:\Users\Acer\PycharmProjects\pythonProject\pythonProject\MicroBlog-Mega-Toturial\NATO-alphabet-start\lib\site-packages\wtforms\fields\core.py", line 242, in validate
    stop_validation = self._run_validation_chain(form, chain)
  File "C:\Users\Acer\PycharmProjects\pythonProject\pythonProject\MicroBlog-Mega-Toturial\NATO-alphabet-start\lib\site-packages\wtforms\fields\core.py", line 262, in _run_validation_chain
    validator(form, self)
TypeError: EditProfileForm.validate_username() takes 1 positional argument but 2 were given
2022-02-08 10:00:03,246 ERROR: Exception on /edit_profile [POST] [in C:\Users\Acer\PycharmProjects\pythonProject\pythonProject\MicroBlog-Mega-Toturial\NATO-alphabet-start\lib\site-packages\flask\app.py:1457]
Traceback (most recent call last):
  File "C:\Users\Acer\PycharmProjects\pythonProject\pythonProject\MicroBlog-Mega-Toturial\NATO-alphabet-start\lib\site-packages\flask\app.py", line 2073, in wsgi_app
    response = self.full_dispatch_request()
  File "C:\Users\Acer\PycharmProjects\pythonProject\pythonProject\MicroBlog-Mega-Toturial\NATO-alphabet-start\lib\site-packages\flask\app.py", line 1518, in full_dispatch_request
    rv = self.handle_user_exception(e)
  File "C:\Users\Acer\PycharmProjects\pythonProject\pythonProject\MicroBlog-Mega-Toturial\NATO-alphabet-start\lib\site-packages\flask\app.py", line 1516, in full_dispatch_request
    rv = self.dispatch_request()
  File "C:\Users\Acer\PycharmProjects\pythonProject\pythonProject\MicroBlog-Mega-Toturial\NATO-alphabet-start\lib\site-packages\flask\app.py", line 1502, in dispatch_request
    return self.ensure_sync(self.view_functions[rule.endpoint])(**req.view_args)
  File "C:\Users\Acer\PycharmProjects\pythonProject\pythonProject\MicroBlog-Mega-Toturial\NATO-alphabet-start\lib\site-packages\flask_login\utils.py", line 272, in decorated_view
    return func(*args, **kwargs)
  File "C:\Users\Acer\PycharmProjects\pythonProject\pythonProject\MicroBlog-Mega-Toturial\app\routes.py", line 96, in edit_profile
    if form.validate_on_submit():
  File "C:\Users\Acer\PycharmProjects\pythonProject\pythonProject\MicroBlog-Mega-Toturial\NATO-alphabet-start\lib\site-packages\flask_wtf\form.py", line 86, in validate_on_submit
    return self.is_submitted() and self.validate()
  File "C:\Users\Acer\PycharmProjects\pythonProject\pythonProject\MicroBlog-Mega-Toturial\NATO-alphabet-start\lib\site-packages\wtforms\form.py", line 329, in validate
    return super().validate(extra)
  File "C:\Users\Acer\PycharmProjects\pythonProject\pythonProject\MicroBlog-Mega-Toturial\NATO-alphabet-start\lib\site-packages\wtforms\form.py", line 146, in validate
    if not field.validate(self, extra):
  File "C:\Users\Acer\PycharmProjects\pythonProject\pythonProject\MicroBlog-Mega-Toturial\NATO-alphabet-start\lib\site-packages\wtforms\fields\core.py", line 242, in validate
    stop_validation = self._run_validation_chain(form, chain)
  File "C:\Users\Acer\PycharmProjects\pythonProject\pythonProject\MicroBlog-Mega-Toturial\NATO-alphabet-start\lib\site-packages\wtforms\fields\core.py", line 262, in _run_validation_chain
    validator(form, self)
TypeError: EditProfileForm.validate_username() takes 1 positional argument but 2 were given
2022-02-08 10:02:38,688 INFO: Microblog startup [in C:\Users\Acer\PycharmProjects\pythonProject\pythonProject\MicroBlog-Mega-Toturial\app\__init__.py:55]
2022-02-08 10:03:38,149 INFO: Microblog startup [in C:\Users\Acer\PycharmProjects\pythonProject\pythonProject\MicroBlog-Mega-Toturial\app\__init__.py:55]
2022-02-08 10:12:14,818 INFO: Microblog startup [in C:\Users\Acer\PycharmProjects\pythonProject\pythonProject\MicroBlog-Mega-Toturial\app\__init__.py:55]
2022-02-08 10:12:43,872 INFO: Microblog startup [in C:\Users\Acer\PycharmProjects\pythonProject\pythonProject\MicroBlog-Mega-Toturial\app\__init__.py:55]
2022-02-08 16:40:03,476 INFO: Microblog startup [in C:\Users\Acer\PycharmProjects\pythonProject\pythonProject\MicroBlog-Mega-Toturial\app\__init__.py:55]
2022-02-08 17:04:06,878 INFO: Microblog startup [in C:\Users\Acer\PycharmProjects\pythonProject\pythonProject\MicroBlog-Mega-Toturial\app\__init__.py:55]
2022-02-08 17:07:18,815 INFO: Microblog startup [in C:\Users\Acer\PycharmProjects\pythonProject\pythonProject\MicroBlog-Mega-Toturial\app\__init__.py:55]
2022-02-08 17:07:27,265 ERROR: Exception on /user/mohamed [GET] [in C:\Users\Acer\PycharmProjects\pythonProject\pythonProject\MicroBlog-Mega-Toturial\NATO-alphabet-start\lib\site-packages\flask\app.py:1457]
Traceback (most recent call last):
  File "C:\Users\Acer\PycharmProjects\pythonProject\pythonProject\MicroBlog-Mega-Toturial\NATO-alphabet-start\lib\site-packages\flask\app.py", line 2073, in wsgi_app
    response = self.full_dispatch_request()
  File "C:\Users\Acer\PycharmProjects\pythonProject\pythonProject\MicroBlog-Mega-Toturial\NATO-alphabet-start\lib\site-packages\flask\app.py", line 1518, in full_dispatch_request
    rv = self.handle_user_exception(e)
  File "C:\Users\Acer\PycharmProjects\pythonProject\pythonProject\MicroBlog-Mega-Toturial\NATO-alphabet-start\lib\site-packages\flask\app.py", line 1516, in full_dispatch_request
    rv = self.dispatch_request()
  File "C:\Users\Acer\PycharmProjects\pythonProject\pythonProject\MicroBlog-Mega-Toturial\NATO-alphabet-start\lib\site-packages\flask\app.py", line 1502, in dispatch_request
    return self.ensure_sync(self.view_functions[rule.endpoint])(**req.view_args)
  File "C:\Users\Acer\PycharmProjects\pythonProject\pythonProject\MicroBlog-Mega-Toturial\NATO-alphabet-start\lib\site-packages\flask_login\utils.py", line 272, in decorated_view
    return func(*args, **kwargs)
  File "C:\Users\Acer\PycharmProjects\pythonProject\pythonProject\MicroBlog-Mega-Toturial\app\routes.py", line 80, in user
    print(current_user.followers.c.follower_id)
AttributeError: 'AppenderBaseQuery' object has no attribute 'c'
2022-02-08 17:08:09,912 ERROR: Exception on /user/mohamed [GET] [in C:\Users\Acer\PycharmProjects\pythonProject\pythonProject\MicroBlog-Mega-Toturial\NATO-alphabet-start\lib\site-packages\flask\app.py:1457]
Traceback (most recent call last):
  File "C:\Users\Acer\PycharmProjects\pythonProject\pythonProject\MicroBlog-Mega-Toturial\NATO-alphabet-start\lib\site-packages\flask\app.py", line 2073, in wsgi_app
    response = self.full_dispatch_request()
  File "C:\Users\Acer\PycharmProjects\pythonProject\pythonProject\MicroBlog-Mega-Toturial\NATO-alphabet-start\lib\site-packages\flask\app.py", line 1518, in full_dispatch_request
    rv = self.handle_user_exception(e)
  File "C:\Users\Acer\PycharmProjects\pythonProject\pythonProject\MicroBlog-Mega-Toturial\NATO-alphabet-start\lib\site-packages\flask\app.py", line 1516, in full_dispatch_request
    rv = self.dispatch_request()
  File "C:\Users\Acer\PycharmProjects\pythonProject\pythonProject\MicroBlog-Mega-Toturial\NATO-alphabet-start\lib\site-packages\flask\app.py", line 1502, in dispatch_request
    return self.ensure_sync(self.view_functions[rule.endpoint])(**req.view_args)
  File "C:\Users\Acer\PycharmProjects\pythonProject\pythonProject\MicroBlog-Mega-Toturial\NATO-alphabet-start\lib\site-packages\flask_login\utils.py", line 272, in decorated_view
    return func(*args, **kwargs)
  File "C:\Users\Acer\PycharmProjects\pythonProject\pythonProject\MicroBlog-Mega-Toturial\app\routes.py", line 80, in user
    print(current_user.followers.c.follower_id)
AttributeError: 'AppenderBaseQuery' object has no attribute 'c'
2022-02-08 17:08:32,925 INFO: Microblog startup [in C:\Users\Acer\PycharmProjects\pythonProject\pythonProject\MicroBlog-Mega-Toturial\app\__init__.py:55]
