2022-02-15 10:37:17,247 ERROR: Exception on /auth/login [POST] [in C:\python10.2\lib\site-packages\flask\app.py:1891]
Traceback (most recent call last):
  File "C:\python10.2\lib\site-packages\sqlalchemy\util\_collections.py", line 1020, in __call__
    return self.registry[key]
KeyError: 11304

During handling of the above exception, another exception occurred:

Traceback (most recent call last):
  File "C:\python10.2\lib\site-packages\flask\app.py", line 2447, in wsgi_app
    response = self.full_dispatch_request()
  File "C:\python10.2\lib\site-packages\flask\app.py", line 1952, in full_dispatch_request
    rv = self.handle_user_exception(e)
  File "C:\python10.2\lib\site-packages\flask\app.py", line 1821, in handle_user_exception
    reraise(exc_type, exc_value, tb)
  File "C:\python10.2\lib\site-packages\flask\_compat.py", line 39, in reraise
    raise value
  File "C:\python10.2\lib\site-packages\flask\app.py", line 1950, in full_dispatch_request
    rv = self.dispatch_request()
  File "C:\python10.2\lib\site-packages\flask\app.py", line 1936, in dispatch_request
    return self.view_functions[rule.endpoint](**req.view_args)
  File "C:\Users\Acer\PycharmProjects\pythonProject\pythonProject\MicroBlog-Mega-Toturial\app\auth\routes.py", line 41, in login
    user = User.query.filter_by(username=form.username.data).first()
  File "C:\python10.2\lib\site-packages\flask_sqlalchemy\__init__.py", line 514, in __get__
    return type.query_class(mapper, session=self.sa.session())
  File "C:\python10.2\lib\site-packages\sqlalchemy\orm\scoping.py", line 78, in __call__
    return self.registry()
  File "C:\python10.2\lib\site-packages\sqlalchemy\util\_collections.py", line 1022, in __call__
    return self.registry.setdefault(key, self.createfunc())
  File "C:\python10.2\lib\site-packages\sqlalchemy\orm\session.py", line 3286, in __call__
    return self.class_(**local_kw)
  File "C:\python10.2\lib\site-packages\flask_sqlalchemy\__init__.py", line 138, in __init__
    bind = options.pop('bind', None) or db.engine
  File "C:\python10.2\lib\site-packages\flask_sqlalchemy\__init__.py", line 943, in engine
    return self.get_engine()
  File "C:\python10.2\lib\site-packages\flask_sqlalchemy\__init__.py", line 962, in get_engine
    return connector.get_engine()
  File "C:\python10.2\lib\site-packages\flask_sqlalchemy\__init__.py", line 556, in get_engine
    self._engine = rv = self._sa.create_engine(sa_url, options)
  File "C:\python10.2\lib\site-packages\flask_sqlalchemy\__init__.py", line 972, in create_engine
    return sqlalchemy.create_engine(sa_url, **engine_opts)
  File "C:\python10.2\lib\site-packages\sqlalchemy\engine\__init__.py", line 500, in create_engine
    return strategy.create(*args, **kwargs)
  File "C:\python10.2\lib\site-packages\sqlalchemy\engine\strategies.py", line 87, in create
    dbapi = dialect_cls.dbapi(**dbapi_args)
  File "C:\python10.2\lib\site-packages\sqlalchemy\dialects\mysql\pymysql.py", line 62, in dbapi
    return __import__("pymysql")
ModuleNotFoundError: No module named 'pymysql'
2022-02-15 10:37:50,048 ERROR: Exception on /auth/login [POST] [in C:\python10.2\lib\site-packages\flask\app.py:1891]
Traceback (most recent call last):
  File "C:\python10.2\lib\site-packages\sqlalchemy\util\_collections.py", line 1020, in __call__
    return self.registry[key]
KeyError: 13696

During handling of the above exception, another exception occurred:

Traceback (most recent call last):
  File "C:\python10.2\lib\site-packages\flask\app.py", line 2447, in wsgi_app
    response = self.full_dispatch_request()
  File "C:\python10.2\lib\site-packages\flask\app.py", line 1952, in full_dispatch_request
    rv = self.handle_user_exception(e)
  File "C:\python10.2\lib\site-packages\flask\app.py", line 1821, in handle_user_exception
    reraise(exc_type, exc_value, tb)
  File "C:\python10.2\lib\site-packages\flask\_compat.py", line 39, in reraise
    raise value
  File "C:\python10.2\lib\site-packages\flask\app.py", line 1950, in full_dispatch_request
    rv = self.dispatch_request()
  File "C:\python10.2\lib\site-packages\flask\app.py", line 1936, in dispatch_request
    return self.view_functions[rule.endpoint](**req.view_args)
  File "C:\Users\Acer\PycharmProjects\pythonProject\pythonProject\MicroBlog-Mega-Toturial\app\auth\routes.py", line 41, in login
    user = User.query.filter_by(username=form.username.data).first()
  File "C:\python10.2\lib\site-packages\flask_sqlalchemy\__init__.py", line 514, in __get__
    return type.query_class(mapper, session=self.sa.session())
  File "C:\python10.2\lib\site-packages\sqlalchemy\orm\scoping.py", line 78, in __call__
    return self.registry()
  File "C:\python10.2\lib\site-packages\sqlalchemy\util\_collections.py", line 1022, in __call__
    return self.registry.setdefault(key, self.createfunc())
  File "C:\python10.2\lib\site-packages\sqlalchemy\orm\session.py", line 3286, in __call__
    return self.class_(**local_kw)
  File "C:\python10.2\lib\site-packages\flask_sqlalchemy\__init__.py", line 138, in __init__
    bind = options.pop('bind', None) or db.engine
  File "C:\python10.2\lib\site-packages\flask_sqlalchemy\__init__.py", line 943, in engine
    return self.get_engine()
  File "C:\python10.2\lib\site-packages\flask_sqlalchemy\__init__.py", line 962, in get_engine
    return connector.get_engine()
  File "C:\python10.2\lib\site-packages\flask_sqlalchemy\__init__.py", line 556, in get_engine
    self._engine = rv = self._sa.create_engine(sa_url, options)
  File "C:\python10.2\lib\site-packages\flask_sqlalchemy\__init__.py", line 972, in create_engine
    return sqlalchemy.create_engine(sa_url, **engine_opts)
  File "C:\python10.2\lib\site-packages\sqlalchemy\engine\__init__.py", line 500, in create_engine
    return strategy.create(*args, **kwargs)
  File "C:\python10.2\lib\site-packages\sqlalchemy\engine\strategies.py", line 87, in create
    dbapi = dialect_cls.dbapi(**dbapi_args)
  File "C:\python10.2\lib\site-packages\sqlalchemy\dialects\mysql\pymysql.py", line 62, in dbapi
    return __import__("pymysql")
ModuleNotFoundError: No module named 'pymysql'
2022-02-15 10:39:37,978 ERROR: Exception on /auth/login [POST] [in C:\python10.2\lib\site-packages\flask\app.py:1891]
Traceback (most recent call last):
  File "C:\python10.2\lib\site-packages\sqlalchemy\util\_collections.py", line 1020, in __call__
    return self.registry[key]
KeyError: 5588

During handling of the above exception, another exception occurred:

Traceback (most recent call last):
  File "C:\python10.2\lib\site-packages\flask\app.py", line 2447, in wsgi_app
    response = self.full_dispatch_request()
  File "C:\python10.2\lib\site-packages\flask\app.py", line 1952, in full_dispatch_request
    rv = self.handle_user_exception(e)
  File "C:\python10.2\lib\site-packages\flask\app.py", line 1821, in handle_user_exception
    reraise(exc_type, exc_value, tb)
  File "C:\python10.2\lib\site-packages\flask\_compat.py", line 39, in reraise
    raise value
  File "C:\python10.2\lib\site-packages\flask\app.py", line 1950, in full_dispatch_request
    rv = self.dispatch_request()
  File "C:\python10.2\lib\site-packages\flask\app.py", line 1936, in dispatch_request
    return self.view_functions[rule.endpoint](**req.view_args)
  File "C:\Users\Acer\PycharmProjects\pythonProject\pythonProject\MicroBlog-Mega-Toturial\app\auth\routes.py", line 41, in login
    user = User.query.filter_by(username=form.username.data).first()
  File "C:\python10.2\lib\site-packages\flask_sqlalchemy\__init__.py", line 514, in __get__
    return type.query_class(mapper, session=self.sa.session())
  File "C:\python10.2\lib\site-packages\sqlalchemy\orm\scoping.py", line 78, in __call__
    return self.registry()
  File "C:\python10.2\lib\site-packages\sqlalchemy\util\_collections.py", line 1022, in __call__
    return self.registry.setdefault(key, self.createfunc())
  File "C:\python10.2\lib\site-packages\sqlalchemy\orm\session.py", line 3286, in __call__
    return self.class_(**local_kw)
  File "C:\python10.2\lib\site-packages\flask_sqlalchemy\__init__.py", line 138, in __init__
    bind = options.pop('bind', None) or db.engine
  File "C:\python10.2\lib\site-packages\flask_sqlalchemy\__init__.py", line 943, in engine
    return self.get_engine()
  File "C:\python10.2\lib\site-packages\flask_sqlalchemy\__init__.py", line 962, in get_engine
    return connector.get_engine()
  File "C:\python10.2\lib\site-packages\flask_sqlalchemy\__init__.py", line 556, in get_engine
    self._engine = rv = self._sa.create_engine(sa_url, options)
  File "C:\python10.2\lib\site-packages\flask_sqlalchemy\__init__.py", line 972, in create_engine
    return sqlalchemy.create_engine(sa_url, **engine_opts)
  File "C:\python10.2\lib\site-packages\sqlalchemy\engine\__init__.py", line 500, in create_engine
    return strategy.create(*args, **kwargs)
  File "C:\python10.2\lib\site-packages\sqlalchemy\engine\strategies.py", line 87, in create
    dbapi = dialect_cls.dbapi(**dbapi_args)
  File "C:\python10.2\lib\site-packages\sqlalchemy\dialects\mysql\pymysql.py", line 62, in dbapi
    return __import__("pymysql")
ModuleNotFoundError: No module named 'pymysql'
2022-02-15 10:39:59,502 INFO: Microblog startup [in C:\Users\Acer\PycharmProjects\pythonProject\pythonProject\MicroBlog-Mega-Toturial\app\__init__.py:74]
